Workbook

Sheet Tests
A1: ="ID Test" -> ID Test | B1: ="Module" -> Module | C1: ="Fonctionnalité" -> Fonctionnalité | D1: ="Description du cas de test" -> Description du cas de test | E1: ="Pré-conditions" -> Pré-conditions | F1: ="Étapes" -> Étapes | G1: ="Données de test" -> Données de test | H1: ="Résultat attendu" -> Résultat attendu | I1: ="Statut" -> Statut | J1: ="Criticité" -> Criticité | K1: ="Responsable" -> Responsable
A2: ="ACC-01" -> ACC-01 | B2: ="Accueil" -> Accueil | C2: ="Affichage page d'accueil" -> Affichage page d'accueil | D2: ="Vérifier que la page d'accueil s'affiche correctement au chargement de l'application." -> Vérifier que la page d'accueil s'affiche correctement au chargement de l'application. | E2: ="Application frontend et backend accessibles." -> Application frontend et backend accessibles. | F2: ="Ouvrir l'URL racine de l'application." -> Ouvrir l'URL racine de l'application. | G2: ="Aucune donnée." -> Aucune donnée. | H2: ="La page d'accueil se charge sans erreur, avec le contenu principal et les CTA visibles." -> La page d'accueil se charge sans erreur, avec le contenu principal et les CTA visibles. | I2: =Légende!B$2 -> OK | J2: =Légende!C$4 -> Moyenne | K2: =Légende!D$2 -> DA SILVA Jocelin | L2: =""
A3: ="ACC-02" -> ACC-02 | B3: ="Accueil" -> Accueil | C3: ="Navigation rapide" -> Navigation rapide | D3: ="Vérifier que les liens de navigation depuis l'accueil redirigent vers les bonnes pages." -> Vérifier que les liens de navigation depuis l'accueil redirigent vers les bonnes pages. | E3: ="Application ouverte sur la page d'accueil." -> Application ouverte sur la page d'accueil. | F3: ="Cliquer sur les liens ou boutons vers Compte, Informations et Activités." -> Cliquer sur les liens ou boutons vers Compte, Informations et Activités. | G3: ="Aucune donnée." -> Aucune donnée. | H3: ="Chaque action redirige vers la route attendue sans erreur de chargement." -> Chaque action redirige vers la route attendue sans erreur de chargement. | I3: =Légende!B$2 -> OK | J3: =Légende!C$4 -> Moyenne | K3: =Légende!D$2 -> DA SILVA Jocelin | L3: =""
A4: ="ACC-03" -> ACC-03 | B4: ="Accueil" -> Accueil | C4: ="Indicateurs dynamiques" -> Indicateurs dynamiques | D4: ="Vérifier le chargement des compteurs dynamiques affichés sur la page d'accueil." -> Vérifier le chargement des compteurs dynamiques affichés sur la page d'accueil. | E4: ="Backend opérationnel et données disponibles." -> Backend opérationnel et données disponibles. | F4: ="Ouvrir l'accueil et observer les compteurs." -> Ouvrir l'accueil et observer les compteurs. | G4: ="Données de démonstration en base." -> Données de démonstration en base. | H4: ="Les compteurs s'affichent avec des valeurs cohérentes et sans blocage de vue." -> Les compteurs s'affichent avec des valeurs cohérentes et sans blocage de vue. | I4: =Légende!B$2 -> OK | J4: =Légende!C$4 -> Moyenne | K4: =Légende!D$2 -> DA SILVA Jocelin | L4: =""
A5: ="AUTH-01" -> AUTH-01 | B5: ="Compte" -> Compte | C5: ="Inscription utilisateur" -> Inscription utilisateur | D5: ="Vérifier qu'un utilisateur peut créer un compte avec des informations valides." -> Vérifier qu'un utilisateur peut créer un compte avec des informations valides. | E5: ="Aucun compte existant avec l'adresse email utilisée." -> Aucun compte existant avec l'adresse email utilisée. | F5: ="Ouvrir le formulaire d'inscription, saisir les champs obligatoires, valider." -> Ouvrir le formulaire d'inscription, saisir les champs obligatoires, valider. | G5: ="Email valide, mot de passe conforme, confirmation identique." -> Email valide, mot de passe conforme, confirmation identique. | H5: ="Le compte est créé et un message de succès est affiché." -> Le compte est créé et un message de succès est affiché. | I5: =Légende!B$2 -> OK | J5: =Légende!C$2 -> Critique | K5: =Légende!D$2 -> DA SILVA Jocelin | L5: =""
A6: ="AUTH-02" -> AUTH-02 | B6: ="Compte" -> Compte | C6: ="Validation inscription" -> Validation inscription | D6: ="Vérifier le refus d'une inscription avec mot de passe invalide ou confirmation différente." -> Vérifier le refus d'une inscription avec mot de passe invalide ou confirmation différente. | E6: ="Formulaire d'inscription accessible." -> Formulaire d'inscription accessible. | F6: ="Saisir des données invalides puis valider." -> Saisir des données invalides puis valider. | G6: ="Email valide, mot de passe trop court ou confirmation différente." -> Email valide, mot de passe trop court ou confirmation différente. | H6: ="La création est refusée et un message d'erreur explicite est affiché." -> La création est refusée et un message d'erreur explicite est affiché. | I6: =Légende!B$2 -> OK | J6: =Légende!C$3 -> Haute | K6: =Légende!D$2 -> DA SILVA Jocelin | L6: =""
A7: ="AUTH-03" -> AUTH-03 | B7: ="Compte" -> Compte | C7: ="Connexion utilisateur" -> Connexion utilisateur | D7: ="Vérifier qu'un utilisateur peut se connecter avec des identifiants valides." -> Vérifier qu'un utilisateur peut se connecter avec des identifiants valides. | E7: ="Un compte utilisateur existe déjà." -> Un compte utilisateur existe déjà. | F7: ="Renseigner email et mot de passe puis valider la connexion." -> Renseigner email et mot de passe puis valider la connexion. | G7: ="Compte utilisateur actif, mot de passe correct." -> Compte utilisateur actif, mot de passe correct. | H7: ="L'utilisateur est authentifié, le jeton est stocké et la vue de compte bascule en mode connecté." -> L'utilisateur est authentifié, le jeton est stocké et la vue de compte bascule en mode connecté. | I7: =Légende!B$2 -> OK | J7: =Légende!C$2 -> Critique | K7: =Légende!D$2 -> DA SILVA Jocelin | L7: =""
A8: ="AUTH-04" -> AUTH-04 | B8: ="Compte" -> Compte | C8: ="Connexion invalide" -> Connexion invalide | D8: ="Vérifier le comportement en cas d'identifiants incorrects." -> Vérifier le comportement en cas d'identifiants incorrects. | E8: ="Formulaire de connexion accessible." -> Formulaire de connexion accessible. | F8: ="Saisir un email ou mot de passe incorrect puis valider." -> Saisir un email ou mot de passe incorrect puis valider. | G8: ="Email inconnu ou mot de passe erroné." -> Email inconnu ou mot de passe erroné. | H8: ="La connexion échoue et un message d'erreur est affiché sans authentification partielle." -> La connexion échoue et un message d'erreur est affiché sans authentification partielle. | I8: =Légende!B$2 -> OK | J8: =Légende!C$3 -> Haute | K8: =Légende!D$2 -> DA SILVA Jocelin | L8: =""
A9: ="AUTH-05" -> AUTH-05 | B9: ="Compte" -> Compte | C9: ="Déconnexion" -> Déconnexion | D9: ="Vérifier que la déconnexion réinitialise la session." -> Vérifier que la déconnexion réinitialise la session. | E9: ="Utilisateur connecté." -> Utilisateur connecté. | F9: ="Cliquer sur le bouton de déconnexion." -> Cliquer sur le bouton de déconnexion. | G9: ="Session active." -> Session active. | H9: ="Les données de session sont supprimées, l'interface revient à l'état non connecté." -> Les données de session sont supprimées, l'interface revient à l'état non connecté. | I9: =Légende!B$2 -> OK | J9: =Légende!C$2 -> Critique | K9: =Légende!D$2 -> DA SILVA Jocelin | L9: =""
A10: ="AUTH-06" -> AUTH-06 | B10: ="Compte" -> Compte | C10: ="Restauration de session" -> Restauration de session | D10: ="Vérifier que la session locale est restaurée au rechargement." -> Vérifier que la session locale est restaurée au rechargement. | E10: ="Utilisateur déjà authentifié avec token ou profil local." -> Utilisateur déjà authentifié avec token ou profil local. | F10: ="Recharger la page ou rouvrir l'application." -> Recharger la page ou rouvrir l'application. | G10: ="Session locale valide." -> Session locale valide. | H10: ="L'utilisateur reste identifié et ses informations sont réaffichées." -> L'utilisateur reste identifié et ses informations sont réaffichées. | I10: =Légende!B$2 -> OK | J10: =Légende!C$4 -> Moyenne | K10: =Légende!D$2 -> DA SILVA Jocelin | L10: =""
A11: ="AUTH-07" -> AUTH-07 | B11: ="Compte" -> Compte | C11: ="Mot de passe oublié" -> Mot de passe oublié | D11: ="Vérifier qu'un message explicite est affiché lorsqu'on demande une réinitialisation sans email." -> Vérifier qu'un message explicite est affiché lorsqu'on demande une réinitialisation sans email. | E11: ="Formulaire de compte accessible." -> Formulaire de compte accessible. | F11: ="Cliquer sur l'action mot de passe oublié sans renseigner d'adresse e-mail." -> Cliquer sur l'action mot de passe oublié sans renseigner d'adresse e-mail. | G11: ="Aucun email saisi." -> Aucun email saisi. | H11: ="L'application affiche une demande de saisie de l'adresse e-mail." -> L'application affiche une demande de saisie de l'adresse e-mail. | I11: =Légende!B$2 -> OK | J11: =Légende!C$5 -> Faible | K11: =Légende!D$2 -> DA SILVA Jocelin | L11: =""
A12: ="AUTH-08" -> AUTH-08 | B12: ="Compte" -> Compte | C12: ="Inscription puis connexion" -> Inscription puis connexion | D12: ="Vérifier qu'un compte nouvellement créé peut se connecter immédiatement." -> Vérifier qu'un compte nouvellement créé peut se connecter immédiatement. | E12: ="Aucun compte existant avec l'adresse utilisée." -> Aucun compte existant avec l'adresse utilisée. | F12: ="Créer un compte puis se connecter avec les mêmes identifiants." -> Créer un compte puis se connecter avec les mêmes identifiants. | G12: ="Email valide et mot de passe conforme." -> Email valide et mot de passe conforme. | H12: ="L'inscription réussit puis la connexion retourne la session attendue." -> L'inscription réussit puis la connexion retourne la session attendue. | I12: =Légende!B$2 -> OK | J12: =Légende!C$2 -> Critique | K12: =Légende!D$2 -> DA SILVA Jocelin | L12: =""
A13: ="PROF-01" -> PROF-01 | B13: ="Compte" -> Compte | C13: ="Mise à jour du profil" -> Mise à jour du profil | D13: ="Vérifier qu'un utilisateur connecté peut mettre à jour ses informations de profil." -> Vérifier qu'un utilisateur connecté peut mettre à jour ses informations de profil. | E13: ="Utilisateur connecté avec profil éditable." -> Utilisateur connecté avec profil éditable. | F13: ="Ouvrir le profil, modifier les champs autorisés, enregistrer." -> Ouvrir le profil, modifier les champs autorisés, enregistrer. | G13: ="Nouveau prénom, nouveau nom ou email valide." -> Nouveau prénom, nouveau nom ou email valide. | H13: ="Les modifications sont enregistrées et reflétées dans l'interface." -> Les modifications sont enregistrées et reflétées dans l'interface. | I13: =Légende!B$2 -> OK | J13: =Légende!C$3 -> Haute | K13: =Légende!D$2 -> DA SILVA Jocelin | L13: =""
A14: ="INF-01" -> INF-01 | B14: ="Informations" -> Informations | C14: ="Liste des articles publiés" -> Liste des articles publiés | D14: ="Vérifier l'affichage des informations publiées uniquement." -> Vérifier l'affichage des informations publiées uniquement. | E14: ="Backend opérationnel, contenus publiés en base." -> Backend opérationnel, contenus publiés en base. | F14: ="Ouvrir la page Informations." -> Ouvrir la page Informations. | G14: ="Articles publiés et non publiés en base." -> Articles publiés et non publiés en base. | H14: ="Seuls les contenus publiés sont visibles dans la liste." -> Seuls les contenus publiés sont visibles dans la liste. | I14: =Légende!B$2 -> OK | J14: =Légende!C$2 -> Critique | K14: =Légende!D$2 -> DA SILVA Jocelin | L14: =""
A15: ="INF-02" -> INF-02 | B15: ="Informations" -> Informations | C15: ="Filtrage par catégorie" -> Filtrage par catégorie | D15: ="Vérifier que le filtrage des informations par catégorie fonctionne." -> Vérifier que le filtrage des informations par catégorie fonctionne. | E15: ="Page Informations chargée avec plusieurs catégories." -> Page Informations chargée avec plusieurs catégories. | F15: ="Sélectionner une catégorie puis observer la liste." -> Sélectionner une catégorie puis observer la liste. | G15: ="Catégorie existante." -> Catégorie existante. | H15: ="La liste est filtrée selon la catégorie sélectionnée." -> La liste est filtrée selon la catégorie sélectionnée. | I15: =Légende!B$2 -> OK | J15: =Légende!C$4 -> Moyenne | K15: =Légende!D$2 -> DA SILVA Jocelin | L15: =""
A16: ="INF-03" -> INF-03 | B16: ="Informations" -> Informations | C16: ="Favori article connecté" -> Favori article connecté | D16: ="Vérifier qu'un utilisateur connecté peut ajouter et retirer un article des favoris." -> Vérifier qu'un utilisateur connecté peut ajouter et retirer un article des favoris. | E16: ="Utilisateur connecté et article visible." -> Utilisateur connecté et article visible. | F16: ="Cliquer sur l'icône favori puis recliquer pour retirer." -> Cliquer sur l'icône favori puis recliquer pour retirer. | G16: ="Compte utilisateur actif, article publié." -> Compte utilisateur actif, article publié. | H16: ="Le favori est ajouté puis retiré correctement, avec synchronisation backend." -> Le favori est ajouté puis retiré correctement, avec synchronisation backend. | I16: =Légende!B$2 -> OK | J16: =Légende!C$3 -> Haute | K16: =Légende!D$2 -> DA SILVA Jocelin | L16: =""
A17: ="INF-04" -> INF-04 | B17: ="Informations" -> Informations | C17: ="Favori article non connecté" -> Favori article non connecté | D17: ="Vérifier qu'un utilisateur non connecté est redirigé vers la page compte avant l'ajout en favori." -> Vérifier qu'un utilisateur non connecté est redirigé vers la page compte avant l'ajout en favori. | E17: ="Utilisateur non authentifié." -> Utilisateur non authentifié. | F17: ="Cliquer sur l'icône favori d'un article." -> Cliquer sur l'icône favori d'un article. | G17: ="Aucune session active." -> Aucune session active. | H17: ="L'application redirige vers la page Compte et n'effectue pas l'action." -> L'application redirige vers la page Compte et n'effectue pas l'action. | I17: =Légende!B$2 -> OK | J17: =Légende!C$3 -> Haute | K17: =Légende!D$2 -> DA SILVA Jocelin | L17: =""
A18: ="INF-05" -> INF-05 | B18: ="Informations" -> Informations | C18: ="Chargement initial des articles et catégories" -> Chargement initial des articles et catégories | D18: ="Vérifier que la page charge les articles publiés et les catégories au démarrage." -> Vérifier que la page charge les articles publiés et les catégories au démarrage. | E18: ="Page Informations accessible." -> Page Informations accessible. | F18: ="Ouvrir la page et attendre le chargement initial." -> Ouvrir la page et attendre le chargement initial. | G18: ="Articles publiés et catégories en base." -> Articles publiés et catégories en base. | H18: ="La liste et les filtres apparaissent sans erreur de chargement." -> La liste et les filtres apparaissent sans erreur de chargement. | I18: =Légende!B$2 -> OK | J18: =Légende!C$4 -> Moyenne | K18: =Légende!D$2 -> DA SILVA Jocelin | L18: =""
A19: ="INF-06" -> INF-06 | B19: ="Informations" -> Informations | C19: ="Sélection d'une catégorie" -> Sélection d'une catégorie | D19: ="Vérifier que le changement de catégorie filtre instantanément les articles affichés." -> Vérifier que le changement de catégorie filtre instantanément les articles affichés. | E19: ="Page Informations chargée." -> Page Informations chargée. | F19: ="Cliquer sur une catégorie différente." -> Cliquer sur une catégorie différente. | G19: ="Au moins deux catégories présentes." -> Au moins deux catégories présentes. | H19: ="La sélection modifie la liste visible sans rechargement complet." -> La sélection modifie la liste visible sans rechargement complet. | I19: =Légende!B$2 -> OK | J19: =Légende!C$4 -> Moyenne | K19: =Légende!D$2 -> DA SILVA Jocelin | L19: =""
A20: ="INF-07" -> INF-07 | B20: ="Informations" -> Informations | C20: ="Gestion complète d'un article" -> Gestion complète d'un article | D20: ="Vérifier qu'un administrateur peut créer, modifier, publier puis supprimer un article." -> Vérifier qu'un administrateur peut créer, modifier, publier puis supprimer un article. | E20: ="Utilisateur authentifié avec rôle Admin." -> Utilisateur authentifié avec rôle Admin. | F20: ="Ouvrir l'administration informations et enchaîner les actions sur un article de test." -> Ouvrir l'administration informations et enchaîner les actions sur un article de test. | G20: ="Article de test valide." -> Article de test valide. | H20: ="Les actions s'appliquent correctement et l'état final correspond à la dernière action." -> Les actions s'appliquent correctement et l'état final correspond à la dernière action. | I20: =Légende!B$2 -> OK | J20: =Légende!C$2 -> Critique | K20: =Légende!D$2 -> DA SILVA Jocelin | L20: =""
A21: ="ACT-01" -> ACT-01 | B21: ="Activités" -> Activités | C21: ="Liste des activités actives" -> Liste des activités actives | D21: ="Vérifier l'affichage des activités actives uniquement." -> Vérifier l'affichage des activités actives uniquement. | E21: ="Backend opérationnel, activités actives en base." -> Backend opérationnel, activités actives en base. | F21: ="Ouvrir la page Activités." -> Ouvrir la page Activités. | G21: ="Activités actives et inactives en base." -> Activités actives et inactives en base. | H21: ="Seules les activités actives sont affichées." -> Seules les activités actives sont affichées. | I21: =Légende!B$2 -> OK | J21: =Légende!C$2 -> Critique | K21: =Légende!D$2 -> DA SILVA Jocelin | L21: =""
A22: ="ACT-02" -> ACT-02 | B22: ="Activités" -> Activités | C22: ="Tri des activités" -> Tri des activités | D22: ="Vérifier que le tri par durée ou par nom modifie correctement l'affichage." -> Vérifier que le tri par durée ou par nom modifie correctement l'affichage. | E22: ="Page Activités chargée avec plusieurs cartes." -> Page Activités chargée avec plusieurs cartes. | F22: ="Changer l'option de tri et observer l'ordre." -> Changer l'option de tri et observer l'ordre. | G22: ="Activités avec durées différentes." -> Activités avec durées différentes. | H22: ="L'ordre affiché correspond au critère de tri sélectionné." -> L'ordre affiché correspond au critère de tri sélectionné. | I22: =Légende!B$2 -> OK | J22: =Légende!C$4 -> Moyenne | K22: =Légende!D$2 -> DA SILVA Jocelin | L22: =""
A23: ="ACT-03" -> ACT-03 | B23: ="Activités" -> Activités | C23: ="Filtrage par catégorie" -> Filtrage par catégorie | D23: ="Vérifier le filtrage des activités par catégorie." -> Vérifier le filtrage des activités par catégorie. | E23: ="Page Activités chargée avec plusieurs catégories." -> Page Activités chargée avec plusieurs catégories. | F23: ="Sélectionner une catégorie dans les filtres." -> Sélectionner une catégorie dans les filtres. | G23: ="Catégorie existante." -> Catégorie existante. | H23: ="La liste affichée correspond aux activités de la catégorie choisie." -> La liste affichée correspond aux activités de la catégorie choisie. | I23: =Légende!B$2 -> OK | J23: =Légende!C$4 -> Moyenne | K23: =Légende!D$2 -> DA SILVA Jocelin | L23: =""
A24: ="ACT-04" -> ACT-04 | B24: ="Activités" -> Activités | C24: ="Favori activité connecté" -> Favori activité connecté | D24: ="Vérifier qu'un utilisateur connecté peut ajouter et retirer une activité des favoris." -> Vérifier qu'un utilisateur connecté peut ajouter et retirer une activité des favoris. | E24: ="Utilisateur connecté et activité visible." -> Utilisateur connecté et activité visible. | F24: ="Cliquer sur le favori puis recommencer pour annuler." -> Cliquer sur le favori puis recommencer pour annuler. | G24: ="Compte utilisateur actif, activité active." -> Compte utilisateur actif, activité active. | H24: ="L'activité est marquée puis retirée des favoris sans incohérence visuelle." -> L'activité est marquée puis retirée des favoris sans incohérence visuelle. | I24: =Légende!B$2 -> OK | J24: =Légende!C$3 -> Haute | K24: =Légende!D$2 -> DA SILVA Jocelin | L24: =""
A25: ="ACT-05" -> ACT-05 | B25: ="Activités" -> Activités | C25: ="Favori activité non connecté" -> Favori activité non connecté | D25: ="Vérifier qu'un utilisateur non connecté est redirigé vers la page Compte avant l'ajout en favori." -> Vérifier qu'un utilisateur non connecté est redirigé vers la page Compte avant l'ajout en favori. | E25: ="Utilisateur non authentifié." -> Utilisateur non authentifié. | F25: ="Cliquer sur l'icône favori d'une activité." -> Cliquer sur l'icône favori d'une activité. | G25: ="Aucune session active." -> Aucune session active. | H25: ="L'application redirige vers la page Compte et empêche l'action." -> L'application redirige vers la page Compte et empêche l'action. | I25: =Légende!B$2 -> OK | J25: =Légende!C$3 -> Haute | K25: =Légende!D$2 -> DA SILVA Jocelin | L25: =""
A26: ="ACT-06" -> ACT-06 | B26: ="Activités" -> Activités | C26: ="Chargement initial et filtrage" -> Chargement initial et filtrage | D26: ="Vérifier que la page charge les activités actives et applique les filtres de catégorie au démarrage." -> Vérifier que la page charge les activités actives et applique les filtres de catégorie au démarrage. | E26: ="Backend opérationnel." -> Backend opérationnel. | F26: ="Ouvrir la page Activités et sélectionner un filtre." -> Ouvrir la page Activités et sélectionner un filtre. | G26: ="Activités actives et catégories en base." -> Activités actives et catégories en base. | H26: ="La liste affichée est cohérente et filtrée selon la catégorie choisie." -> La liste affichée est cohérente et filtrée selon la catégorie choisie. | I26: =Légende!B$2 -> OK | J26: =Légende!C$4 -> Moyenne | K26: =Légende!D$2 -> DA SILVA Jocelin | L26: =""
A27: ="ACT-07" -> ACT-07 | B27: ="Activités" -> Activités | C27: ="Sélection de catégorie sans effet secondaire" -> Sélection de catégorie sans effet secondaire | D27: ="Vérifier que le changement de catégorie met à jour l'état local sans casser la liste." -> Vérifier que le changement de catégorie met à jour l'état local sans casser la liste. | E27: ="Page Activités chargée." -> Page Activités chargée. | F27: ="Sélectionner puis modifier un filtre de catégorie." -> Sélectionner puis modifier un filtre de catégorie. | G27: ="Plusieurs catégories disponibles." -> Plusieurs catégories disponibles. | H27: ="L'état interne et l'affichage restent synchronisés." -> L'état interne et l'affichage restent synchronisés. | I27: =Légende!B$2 -> OK | J27: =Légende!C$5 -> Faible | K27: =Légende!D$2 -> DA SILVA Jocelin | L27: =""
A28: ="ACT-08" -> ACT-08 | B28: ="Activités" -> Activités | C28: ="Gestion complète d'une activité" -> Gestion complète d'une activité | D28: ="Vérifier qu'un administrateur peut créer, modifier, désactiver puis supprimer une activité." -> Vérifier qu'un administrateur peut créer, modifier, désactiver puis supprimer une activité. | E28: ="Utilisateur authentifié avec rôle Admin." -> Utilisateur authentifié avec rôle Admin. | F28: ="Ouvrir l'administration activités et enchaîner les actions sur une activité de test." -> Ouvrir l'administration activités et enchaîner les actions sur une activité de test. | G28: ="Activité de test valide." -> Activité de test valide. | H28: ="Les actions s'appliquent correctement et l'état final correspond à la dernière action." -> Les actions s'appliquent correctement et l'état final correspond à la dernière action. | I28: =Légende!B$2 -> OK | J28: =Légende!C$2 -> Critique | K28: =Légende!D$2 -> DA SILVA Jocelin | L28: =""
A29: ="ADM-01" -> ADM-01 | B29: ="Administration" -> Administration | C29: ="Création d'activité" -> Création d'activité | D29: ="Vérifier qu'un administrateur peut créer une activité via le formulaire admin." -> Vérifier qu'un administrateur peut créer une activité via le formulaire admin. | E29: ="Utilisateur authentifié avec rôle Admin." -> Utilisateur authentifié avec rôle Admin. | F29: ="Ouvrir le panneau admin, remplir le formulaire d'activité, valider." -> Ouvrir le panneau admin, remplir le formulaire d'activité, valider. | G29: ="Titre, description, contenu, instructions, catégorie valides." -> Titre, description, contenu, instructions, catégorie valides. | H29: ="L'activité est créée, enregistrée et visible après rafraîchissement." -> L'activité est créée, enregistrée et visible après rafraîchissement. | I29: =Légende!B$2 -> OK | J29: =Légende!C$2 -> Critique | K29: =Légende!D$2 -> DA SILVA Jocelin | L29: =""
A30: ="ADM-02" -> ADM-02 | B30: ="Administration" -> Administration | C30: ="Création d'information" -> Création d'information | D30: ="Vérifier qu'un administrateur peut créer une information via le formulaire admin." -> Vérifier qu'un administrateur peut créer une information via le formulaire admin. | E30: ="Utilisateur authentifié avec rôle Admin." -> Utilisateur authentifié avec rôle Admin. | F30: ="Ouvrir le panneau admin, remplir le formulaire d'information, valider." -> Ouvrir le panneau admin, remplir le formulaire d'information, valider. | G30: ="Titre, contenu, catégorie, niveau de difficulté valides." -> Titre, contenu, catégorie, niveau de difficulté valides. | H30: ="L'information est créée avec succès et l'interface confirme l'opération." -> L'information est créée avec succès et l'interface confirme l'opération. | I30: =Légende!B$2 -> OK | J30: =Légende!C$2 -> Critique | K30: =Légende!D$2 -> DA SILVA Jocelin | L30: =""
A31: ="ADM-03" -> ADM-03 | B31: ="Administration" -> Administration | C31: ="Activation / désactivation" -> Activation / désactivation | D31: ="Vérifier qu'un administrateur peut activer ou désactiver un contenu." -> Vérifier qu'un administrateur peut activer ou désactiver un contenu. | E31: ="Utilisateur authentifié avec rôle Admin." -> Utilisateur authentifié avec rôle Admin. | F31: ="Ouvrir un élément, changer son état, sauvegarder." -> Ouvrir un élément, changer son état, sauvegarder. | G31: ="Activité ou information existante." -> Activité ou information existante. | H31: ="L'état du contenu est mis à jour et reflété dans la liste." -> L'état du contenu est mis à jour et reflété dans la liste. | I31: =Légende!B$2 -> OK | J31: =Légende!C$3 -> Haute | K31: =Légende!D$2 -> DA SILVA Jocelin | L31: =""
A32: ="ADM-04" -> ADM-04 | B32: ="Administration" -> Administration | C32: ="Gestion des utilisateurs" -> Gestion des utilisateurs | D32: ="Vérifier qu'un administrateur peut promouvoir, rétrograder ou désactiver un compte utilisateur." -> Vérifier qu'un administrateur peut promouvoir, rétrograder ou désactiver un compte utilisateur. | E32: ="Utilisateur authentifié avec rôle Admin." -> Utilisateur authentifié avec rôle Admin. | F32: ="Ouvrir la section utilisateurs, choisir un compte et appliquer une action de gestion." -> Ouvrir la section utilisateurs, choisir un compte et appliquer une action de gestion. | G32: ="Compte utilisateur existant." -> Compte utilisateur existant. | H32: ="L'action choisie est appliquée et la liste des comptes reflète le nouvel état." -> L'action choisie est appliquée et la liste des comptes reflète le nouvel état. | I32: =Légende!B$2 -> OK | J32: =Légende!C$3 -> Haute | K32: =Légende!D$2 -> DA SILVA Jocelin | L32: =""
A33: ="ADM-05" -> ADM-05 | B33: ="Administration" -> Administration | C33: ="Chargement initial du tableau de bord" -> Chargement initial du tableau de bord | D33: ="Vérifier que l'administration charge les jeux de données et respecte l'onglet demandé." -> Vérifier que l'administration charge les jeux de données et respecte l'onglet demandé. | E33: ="Utilisateur authentifié avec rôle Admin." -> Utilisateur authentifié avec rôle Admin. | F33: ="Ouvrir l'administration avec un onglet dans l'URL." -> Ouvrir l'administration avec un onglet dans l'URL. | G33: ="Données d'activités, informations, catégories, difficultés et utilisateurs." -> Données d'activités, informations, catégories, difficultés et utilisateurs. | H33: ="Le bon onglet s'ouvre et les données s'affichent au chargement." -> Le bon onglet s'ouvre et les données s'affichent au chargement. | I33: =Légende!B$2 -> OK | J33: =Légende!C$4 -> Moyenne | K33: =Légende!D$2 -> DA SILVA Jocelin | L33: =""
A34: ="ADM-06" -> ADM-06 | B34: ="Administration" -> Administration | C34: ="Tri du tableau activités" -> Tri du tableau activités | D34: ="Vérifier que le tri des activités dans l'administration change bien l'ordre affiché." -> Vérifier que le tri des activités dans l'administration change bien l'ordre affiché. | E34: ="Utilisateur authentifié avec rôle Admin." -> Utilisateur authentifié avec rôle Admin. | F34: ="Cliquer deux fois sur l'en-tête de tri du tableau activités." -> Cliquer deux fois sur l'en-tête de tri du tableau activités. | G34: ="Plusieurs activités avec titres différents." -> Plusieurs activités avec titres différents. | H34: ="Le tri alterne entre croissant et décroissant sans perte de données." -> Le tri alterne entre croissant et décroissant sans perte de données. | I34: =Légende!B$2 -> OK | J34: =Légende!C$5 -> Faible | K34: =Légende!D$2 -> DA SILVA Jocelin | L34: =""
A35: ="ADM-07" -> ADM-07 | B35: ="Administration" -> Administration | C35: ="Répartition des catégories" -> Répartition des catégories | D35: ="Vérifier que les catégories sont réparties entre activités et informations." -> Vérifier que les catégories sont réparties entre activités et informations. | E35: ="Utilisateur authentifié avec rôle Admin." -> Utilisateur authentifié avec rôle Admin. | F35: ="Ouvrir le bloc des catégories dans l'administration." -> Ouvrir le bloc des catégories dans l'administration. | G35: ="Catégories de type activité et information." -> Catégories de type activité et information. | H35: ="Les catégories sont classées dans les bons groupes métier." -> Les catégories sont classées dans les bons groupes métier. | I35: =Légende!B$2 -> OK | J35: =Légende!C$4 -> Moyenne | K35: =Légende!D$2 -> DA SILVA Jocelin | L35: =""
A36: ="CAT-01" -> CAT-01 | B36: ="Administration" -> Administration | C36: ="Gestion des catégories" -> Gestion des catégories | D36: ="Vérifier qu'un administrateur peut consulter, créer et supprimer une catégorie." -> Vérifier qu'un administrateur peut consulter, créer et supprimer une catégorie. | E36: ="Utilisateur authentifié avec rôle Admin." -> Utilisateur authentifié avec rôle Admin. | F36: ="Ouvrir la section catégories, créer une catégorie puis la supprimer." -> Ouvrir la section catégories, créer une catégorie puis la supprimer. | G36: ="Nom de catégorie valide." -> Nom de catégorie valide. | H36: ="La catégorie est ajoutée puis supprimée sans incohérence dans les listes liées." -> La catégorie est ajoutée puis supprimée sans incohérence dans les listes liées. | I36: =Légende!B$2 -> OK | J36: =Légende!C$4 -> Moyenne | K36: =Légende!D$2 -> DA SILVA Jocelin | L36: =""
A37: ="DIF-01" -> DIF-01 | B37: ="Administration" -> Administration | C37: ="Consultation des niveaux de difficulté" -> Consultation des niveaux de difficulté | D37: ="Vérifier que les niveaux de difficulté se chargent correctement dans le panneau admin." -> Vérifier que les niveaux de difficulté se chargent correctement dans le panneau admin. | E37: ="Utilisateur authentifié avec rôle Admin." -> Utilisateur authentifié avec rôle Admin. | F37: ="Ouvrir l'administration et consulter le bloc des difficultés." -> Ouvrir l'administration et consulter le bloc des difficultés. | G37: ="Niveaux de difficulté présents en base." -> Niveaux de difficulté présents en base. | H37: ="Les niveaux disponibles sont affichés sans erreur et alimentent les formulaires concernés." -> Les niveaux disponibles sont affichés sans erreur et alimentent les formulaires concernés. | I37: =Légende!B$2 -> OK | J37: =Légende!C$4 -> Moyenne | K37: =Légende!D$2 -> DA SILVA Jocelin | L37: =""
A38: ="DIF-02" -> DIF-02 | B38: ="Administration" -> Administration | C38: ="Gestion des niveaux de difficulté" -> Gestion des niveaux de difficulté | D38: ="Vérifier qu'un administrateur peut créer, mettre à jour et supprimer un niveau de difficulté." -> Vérifier qu'un administrateur peut créer, mettre à jour et supprimer un niveau de difficulté. | E38: ="Utilisateur authentifié avec rôle Admin." -> Utilisateur authentifié avec rôle Admin. | F38: ="Ouvrir la section difficultés et enchaîner les opérations." -> Ouvrir la section difficultés et enchaîner les opérations. | G38: ="Niveau de difficulté valide." -> Niveau de difficulté valide. | H38: ="Le niveau est correctement maintenu et les formulaires liés restent fonctionnels." -> Le niveau est correctement maintenu et les formulaires liés restent fonctionnels. | I38: =Légende!B$2 -> OK | J38: =Légende!C$4 -> Moyenne | K38: =Légende!D$2 -> DA SILVA Jocelin | L38: =""
A39: ="SEC-01" -> SEC-01 | B39: ="Sécurité" -> Sécurité | C39: ="Injection JWT" -> Injection JWT | D39: ="Vérifier que le jeton JWT est injecté automatiquement dans les requêtes authentifiées." -> Vérifier que le jeton JWT est injecté automatiquement dans les requêtes authentifiées. | E39: ="Utilisateur connecté." -> Utilisateur connecté. | F39: ="Déclencher une requête API protégée depuis le frontend." -> Déclencher une requête API protégée depuis le frontend. | G39: ="Token de session valide." -> Token de session valide. | H39: ="La requête contient l'en-tête Authorization avec le bearer token." -> La requête contient l'en-tête Authorization avec le bearer token. | I39: =Légende!B$2 -> OK | J39: =Légende!C$2 -> Critique | K39: =Légende!D$2 -> DA SILVA Jocelin | L39: =""
A40: ="SEC-02" -> SEC-02 | B40: ="Sécurité" -> Sécurité | C40: ="Accès refusé pour rôle utilisateur" -> Accès refusé pour rôle utilisateur | D40: ="Vérifier qu'un utilisateur standard ne peut pas exécuter une action admin." -> Vérifier qu'un utilisateur standard ne peut pas exécuter une action admin. | E40: ="Utilisateur connecté avec rôle User." -> Utilisateur connecté avec rôle User. | F40: ="Tenter de créer ou modifier un contenu protégé." -> Tenter de créer ou modifier un contenu protégé. | G40: ="Compte non admin." -> Compte non admin. | H40: ="L'API refuse la requête avec un code 403 Forbidden." -> L'API refuse la requête avec un code 403 Forbidden. | I40: =Légende!B$2 -> OK | J40: =Légende!C$2 -> Critique | K40: =Légende!D$2 -> DA SILVA Jocelin | L40: =""
...

Sheet Légende
A1: Légende : | B1: Statut | C1: Criticité | D1: Responsable
B2: OK | C2: Critique | D2: DA SILVA Jocelin
B3: À exécuter | C3: Haute
B4: KO | C4: Moyenne
B5: Bloqué | C5: Faible
